Workbook

Sheet גביה 2026
A1: קומה | B1: דירה | C1: משפחה | D1: בעל דירה | E1: ינואר | F1: פברואר | G1: מרץ | H1: אפריל | I1: מאי | J1: יוני | K1: יולי | L1: אוגוסט | M1: ספטמבר | N1: אוקטובר | O1: נובמבר | P1: דצמבר | Q1: קופה קטנה 2026 | R1: הערות | S1: אסמסכתא | X1: חובות
A2: 1 | B2: 1 | C2: אלייב | E2: 350 | F2: 350 | G2: 350 | H2: 350 | Q2: 500 | X2: {=_xlfn.LET(_xlpm.exclude_list, {19,26,33,38}, _xlpm.current_month_idx, MONTH(TODAY()), _xlpm.month_names, {"ינואר","פברואר","מרץ","אפריל","מאי","יוני","יולי","אוגוסט","ספטמבר","אוקטובר","נובמבר","דצמבר"}, _xlpm.target, 350, _xlpm.apartment, B2, _xlpm.payments, E2:P2, IF(ISNUMBER(MATCH(_xlpm.apartment, _xlpm.exclude_list, 0)), "", _xlfn.LET(_xlpm.debt_list, _xlfn.MAP(_xlfn.SEQUENCE(1, 12), _xlpm.month_names, _xlpm.payments, _xlfn.LAMBDA(_xlpm.idx,_xlpm.m_name,_xlpm.p_val, IF(_xlpm.idx > _xlpm.current_month_idx, "", IF(OR(ISBLANK(_xlpm.p_val), _xlpm.p_val = ""), _xlpm.m_name & " (חוב " & _xlpm.target & ")", IF(_xlpm.p_val < _xlpm.target, _xlpm.m_name & " (חוב " & (_xlpm.target - _xlpm.p_val) & ")", ""))))), _xlpm.summary, _xlfn.TEXTJOIN(", ", TRUE, _xlpm.debt_list), IF(_xlpm.summary <> "", "דירה " & _xlpm.apartment & " - " & _xlpm.summary, ""))))} | Y2: {="היי, להלן רשימת הדירות שטרם העבירו 500 ש''ח לקופה הקטנה: " & _xlfn.TEXTJOIN(", ", TRUE, _xlfn._xlws.FILTER(B2:B61, Q2:Q61<>500, "אין חובות - כולם שילמו!"))}
B3: 2 | C3: פיליפ אלברט | E3: 350 | F3: 350 | G3: 350 | X3: {=_xlfn.LET(_xlpm.exclude_list, {19,26,33,38}, _xlpm.current_month_idx, MONTH(TODAY()), _xlpm.month_names, {"ינואר","פברואר","מרץ","אפריל","מאי","יוני","יולי","אוגוסט","ספטמבר","אוקטובר","נובמבר","דצמבר"}, _xlpm.target, 350, _xlpm.apartment, B3, _xlpm.payments, E3:P3, IF(ISNUMBER(MATCH(_xlpm.apartment, _xlpm.exclude_list, 0)), "", _xlfn.LET(_xlpm.debt_list, _xlfn.MAP(_xlfn.SEQUENCE(1, 12), _xlpm.month_names, _xlpm.payments, _xlfn.LAMBDA(_xlpm.idx,_xlpm.m_name,_xlpm.p_val, IF(_xlpm.idx > _xlpm.current_month_idx, "", IF(OR(ISBLANK(_xlpm.p_val), _xlpm.p_val = ""), _xlpm.m_name & " (חוב " & _xlpm.target & ")", IF(_xlpm.p_val < _xlpm.target, _xlpm.m_name & " (חוב " & (_xlpm.target - _xlpm.p_val) & ")", ""))))), _xlpm.summary, _xlfn.TEXTJOIN(", ", TRUE, _xlpm.debt_list), IF(_xlpm.summary <> "", "דירה " & _xlpm.apartment & " - " & _xlpm.summary, ""))))}
B4: 3 | C4: מנגיסטו | E4: 350 | F4: 350 | G4: 350 | H4: 350 | Q4: 500 | X4: {=_xlfn.LET(_xlpm.exclude_list, {19,26,33,38}, _xlpm.current_month_idx, MONTH(TODAY()), _xlpm.month_names, {"ינואר","פברואר","מרץ","אפריל","מאי","יוני","יולי","אוגוסט","ספטמבר","אוקטובר","נובמבר","דצמבר"}, _xlpm.target, 350, _xlpm.apartment, B4, _xlpm.payments, E4:P4, IF(ISNUMBER(MATCH(_xlpm.apartment, _xlpm.exclude_list, 0)), "", _xlfn.LET(_xlpm.debt_list, _xlfn.MAP(_xlfn.SEQUENCE(1, 12), _xlpm.month_names, _xlpm.payments, _xlfn.LAMBDA(_xlpm.idx,_xlpm.m_name,_xlpm.p_val, IF(_xlpm.idx > _xlpm.current_month_idx, "", IF(OR(ISBLANK(_xlpm.p_val), _xlpm.p_val = ""), _xlpm.m_name & " (חוב " & _xlpm.target & ")", IF(_xlpm.p_val < _xlpm.target, _xlpm.m_name & " (חוב " & (_xlpm.target - _xlpm.p_val) & ")", ""))))), _xlpm.summary, _xlfn.TEXTJOIN(", ", TRUE, _xlpm.debt_list), IF(_xlpm.summary <> "", "דירה " & _xlpm.apartment & " - " & _xlpm.summary, ""))))}
A5: 2 | B5: 4 | C5: רומנו לינצקי | E5: 350 | F5: 350 | G5: 350 | H5: 350 | X5: {=_xlfn.LET(_xlpm.exclude_list, {19,26,33,38}, _xlpm.current_month_idx, MONTH(TODAY()), _xlpm.month_names, {"ינואר","פברואר","מרץ","אפריל","מאי","יוני","יולי","אוגוסט","ספטמבר","אוקטובר","נובמבר","דצמבר"}, _xlpm.target, 350, _xlpm.apartment, B5, _xlpm.payments, E5:P5, IF(ISNUMBER(MATCH(_xlpm.apartment, _xlpm.exclude_list, 0)), "", _xlfn.LET(_xlpm.debt_list, _xlfn.MAP(_xlfn.SEQUENCE(1, 12), _xlpm.month_names, _xlpm.payments, _xlfn.LAMBDA(_xlpm.idx,_xlpm.m_name,_xlpm.p_val, IF(_xlpm.idx > _xlpm.current_month_idx, "", IF(OR(ISBLANK(_xlpm.p_val), _xlpm.p_val = ""), _xlpm.m_name & " (חוב " & _xlpm.target & ")", IF(_xlpm.p_val < _xlpm.target, _xlpm.m_name & " (חוב " & (_xlpm.target - _xlpm.p_val) & ")", ""))))), _xlpm.summary, _xlfn.TEXTJOIN(", ", TRUE, _xlpm.debt_list), IF(_xlpm.summary <> "", "דירה " & _xlpm.apartment & " - " & _xlpm.summary, ""))))}
B6: 5 | C6: ישראלי | D6: בר ברקת | E6: 350 | F6: 350 | G6: 350 | H6: 350 | Q6: 500 | S6: 4816413 | X6: {=_xlfn.LET(_xlpm.exclude_list, {19,26,33,38}, _xlpm.current_month_idx, MONTH(TODAY()), _xlpm.month_names, {"ינואר","פברואר","מרץ","אפריל","מאי","יוני","יולי","אוגוסט","ספטמבר","אוקטובר","נובמבר","דצמבר"}, _xlpm.target, 350, _xlpm.apartment, B6, _xlpm.payments, E6:P6, IF(ISNUMBER(MATCH(_xlpm.apartment, _xlpm.exclude_list, 0)), "", _xlfn.LET(_xlpm.debt_list, _xlfn.MAP(_xlfn.SEQUENCE(1, 12), _xlpm.month_names, _xlpm.payments, _xlfn.LAMBDA(_xlpm.idx,_xlpm.m_name,_xlpm.p_val, IF(_xlpm.idx > _xlpm.current_month_idx, "", IF(OR(ISBLANK(_xlpm.p_val), _xlpm.p_val = ""), _xlpm.m_name & " (חוב " & _xlpm.target & ")", IF(_xlpm.p_val < _xlpm.target, _xlpm.m_name & " (חוב " & (_xlpm.target - _xlpm.p_val) & ")", ""))))), _xlpm.summary, _xlfn.TEXTJOIN(", ", TRUE, _xlpm.debt_list), IF(_xlpm.summary <> "", "דירה " & _xlpm.apartment & " - " & _xlpm.summary, ""))))} | Y6: {="היי, להלן מצב הגבייה לקופה הקטנה:" & CHAR(10) & _xlfn.TEXTJOIN(CHAR(10), TRUE, _xlfn._xlws.FILTER("דירה " & B2:B61 & IF((Q2:Q61>0)*(Q2:Q61<500), " - חסר " & (500-Q2:Q61) & " ש''ח", ""), Q2:Q61<500, "כולם שילמו!"))}
B7: 6 | C7: רביבו | E7: 350 | F7: 350 | G7: 350 | H7: 350 | Q7: 500 | S7: 4177034 | X7: {=_xlfn.LET(_xlpm.exclude_list, {19,26,33,38}, _xlpm.current_month_idx, MONTH(TODAY()), _xlpm.month_names, {"ינואר","פברואר","מרץ","אפריל","מאי","יוני","יולי","אוגוסט","ספטמבר","אוקטובר","נובמבר","דצמבר"}, _xlpm.target, 350, _xlpm.apartment, B7, _xlpm.payments, E7:P7, IF(ISNUMBER(MATCH(_xlpm.apartment, _xlpm.exclude_list, 0)), "", _xlfn.LET(_xlpm.debt_list, _xlfn.MAP(_xlfn.SEQUENCE(1, 12), _xlpm.month_names, _xlpm.payments, _xlfn.LAMBDA(_xlpm.idx,_xlpm.m_name,_xlpm.p_val, IF(_xlpm.idx > _xlpm.current_month_idx, "", IF(OR(ISBLANK(_xlpm.p_val), _xlpm.p_val = ""), _xlpm.m_name & " (חוב " & _xlpm.target & ")", IF(_xlpm.p_val < _xlpm.target, _xlpm.m_name & " (חוב " & (_xlpm.target - _xlpm.p_val) & ")", ""))))), _xlpm.summary, _xlfn.TEXTJOIN(", ", TRUE, _xlpm.debt_list), IF(_xlpm.summary <> "", "דירה " & _xlpm.apartment & " - " & _xlpm.summary, ""))))}
B8: 7 | C8: רות וולמיר | E8: 350 | F8: 350 | G8: 350 | H8: 350 | Q8: 500 | X8: {=_xlfn.LET(_xlpm.exclude_list, {19,26,33,38}, _xlpm.current_month_idx, MONTH(TODAY()), _xlpm.month_names, {"ינואר","פברואר","מרץ","אפריל","מאי","יוני","יולי","אוגוסט","ספטמבר","אוקטובר","נובמבר","דצמבר"}, _xlpm.target, 350, _xlpm.apartment, B8, _xlpm.payments, E8:P8, IF(ISNUMBER(MATCH(_xlpm.apartment, _xlpm.exclude_list, 0)), "", _xlfn.LET(_xlpm.debt_list, _xlfn.MAP(_xlfn.SEQUENCE(1, 12), _xlpm.month_names, _xlpm.payments, _xlfn.LAMBDA(_xlpm.idx,_xlpm.m_name,_xlpm.p_val, IF(_xlpm.idx > _xlpm.current_month_idx, "", IF(OR(ISBLANK(_xlpm.p_val), _xlpm.p_val = ""), _xlpm.m_name & " (חוב " & _xlpm.target & ")", IF(_xlpm.p_val < _xlpm.target, _xlpm.m_name & " (חוב " & (_xlpm.target - _xlpm.p_val) & ")", ""))))), _xlpm.summary, _xlfn.TEXTJOIN(", ", TRUE, _xlpm.debt_list), IF(_xlpm.summary <> "", "דירה " & _xlpm.apartment & " - " & _xlpm.summary, ""))))}
B9: 8 | C9: לב ארי / לב-ארי / רונן / זפירה / מנגסטה יטמין | E9: 350 | F9: 350 | G9: 350 | H9: 350 | X9: {=_xlfn.LET(_xlpm.exclude_list, {19,26,33,38}, _xlpm.current_month_idx, MONTH(TODAY()), _xlpm.month_names, {"ינואר","פברואר","מרץ","אפריל","מאי","יוני","יולי","אוגוסט","ספטמבר","אוקטובר","נובמבר","דצמבר"}, _xlpm.target, 350, _xlpm.apartment, B9, _xlpm.payments, E9:P9, IF(ISNUMBER(MATCH(_xlpm.apartment, _xlpm.exclude_list, 0)), "", _xlfn.LET(_xlpm.debt_list, _xlfn.MAP(_xlfn.SEQUENCE(1, 12), _xlpm.month_names, _xlpm.payments, _xlfn.LAMBDA(_xlpm.idx,_xlpm.m_name,_xlpm.p_val, IF(_xlpm.idx > _xlpm.current_month_idx, "", IF(OR(ISBLANK(_xlpm.p_val), _xlpm.p_val = ""), _xlpm.m_name & " (חוב " & _xlpm.target & ")", IF(_xlpm.p_val < _xlpm.target, _xlpm.m_name & " (חוב " & (_xlpm.target - _xlpm.p_val) & ")", ""))))), _xlpm.summary, _xlfn.TEXTJOIN(", ", TRUE, _xlpm.debt_list), IF(_xlpm.summary <> "", "דירה " & _xlpm.apartment & " - " & _xlpm.summary, ""))))}
A10: 3 | B10: 9 | C10: בייבקוב | E10: 350 | F10: 350 | G10: 350 | H10: 350 | X10: {=_xlfn.LET(_xlpm.exclude_list, {19,26,33,38}, _xlpm.current_month_idx, MONTH(TODAY()), _xlpm.month_names, {"ינואר","פברואר","מרץ","אפריל","מאי","יוני","יולי","אוגוסט","ספטמבר","אוקטובר","נובמבר","דצמבר"}, _xlpm.target, 350, _xlpm.apartment, B10, _xlpm.payments, E10:P10, IF(ISNUMBER(MATCH(_xlpm.apartment, _xlpm.exclude_list, 0)), "", _xlfn.LET(_xlpm.debt_list, _xlfn.MAP(_xlfn.SEQUENCE(1, 12), _xlpm.month_names, _xlpm.payments, _xlfn.LAMBDA(_xlpm.idx,_xlpm.m_name,_xlpm.p_val, IF(_xlpm.idx > _xlpm.current_month_idx, "", IF(OR(ISBLANK(_xlpm.p_val), _xlpm.p_val = ""), _xlpm.m_name & " (חוב " & _xlpm.target & ")", IF(_xlpm.p_val < _xlpm.target, _xlpm.m_name & " (חוב " & (_xlpm.target - _xlpm.p_val) & ")", ""))))), _xlpm.summary, _xlfn.TEXTJOIN(", ", TRUE, _xlpm.debt_list), IF(_xlpm.summary <> "", "דירה " & _xlpm.apartment & " - " & _xlpm.summary, ""))))}
B11: 10 | C11: לאוניד שכטמן | E11: 350 | F11: 350 | G11: 350 | H11: 350 | S11: 4590840 | X11: {=_xlfn.LET(_xlpm.exclude_list, {19,26,33,38}, _xlpm.current_month_idx, MONTH(TODAY()), _xlpm.month_names, {"ינואר","פברואר","מרץ","אפריל","מאי","יוני","יולי","אוגוסט","ספטמבר","אוקטובר","נובמבר","דצמבר"}, _xlpm.target, 350, _xlpm.apartment, B11, _xlpm.payments, E11:P11, IF(ISNUMBER(MATCH(_xlpm.apartment, _xlpm.exclude_list, 0)), "", _xlfn.LET(_xlpm.debt_list, _xlfn.MAP(_xlfn.SEQUENCE(1, 12), _xlpm.month_names, _xlpm.payments, _xlfn.LAMBDA(_xlpm.idx,_xlpm.m_name,_xlpm.p_val, IF(_xlpm.idx > _xlpm.current_month_idx, "", IF(OR(ISBLANK(_xlpm.p_val), _xlpm.p_val = ""), _xlpm.m_name & " (חוב " & _xlpm.target & ")", IF(_xlpm.p_val < _xlpm.target, _xlpm.m_name & " (חוב " & (_xlpm.target - _xlpm.p_val) & ")", ""))))), _xlpm.summary, _xlfn.TEXTJOIN(", ", TRUE, _xlpm.debt_list), IF(_xlpm.summary <> "", "דירה " & _xlpm.apartment & " - " & _xlpm.summary, ""))))}
B12: 11 | C12: מירב לוי / חן לוי | E12: 350 | F12: 350 | G12: 350 | H12: 350 | Q12: 500 | S12: 4795693 | X12: {=_xlfn.LET(_xlpm.exclude_list, {19,26,33,38}, _xlpm.current_month_idx, MONTH(TODAY()), _xlpm.month_names, {"ינואר","פברואר","מרץ","אפריל","מאי","יוני","יולי","אוגוסט","ספטמבר","אוקטובר","נובמבר","דצמבר"}, _xlpm.target, 350, _xlpm.apartment, B12, _xlpm.payments, E12:P12, IF(ISNUMBER(MATCH(_xlpm.apartment, _xlpm.exclude_list, 0)), "", _xlfn.LET(_xlpm.debt_list, _xlfn.MAP(_xlfn.SEQUENCE(1, 12), _xlpm.month_names, _xlpm.payments, _xlfn.LAMBDA(_xlpm.idx,_xlpm.m_name,_xlpm.p_val, IF(_xlpm.idx > _xlpm.current_month_idx, "", IF(OR(ISBLANK(_xlpm.p_val), _xlpm.p_val = ""), _xlpm.m_name & " (חוב " & _xlpm.target & ")", IF(_xlpm.p_val < _xlpm.target, _xlpm.m_name & " (חוב " & (_xlpm.target - _xlpm.p_val) & ")", ""))))), _xlpm.summary, _xlfn.TEXTJOIN(", ", TRUE, _xlpm.debt_list), IF(_xlpm.summary <> "", "דירה " & _xlpm.apartment & " - " & _xlpm.summary, ""))))}
B13: 12 | C13: ברייב יולי / אלירן מנצור | E13: 350 | F13: 350 | G13: 350 | H13: 350 | I13: 30 | J13: 30 | K13: 30 | L13: 30 | M13: 30 | N13: 30 | O13: 30 | P13: 30 | Q13: 500 | X13: {=_xlfn.LET(_xlpm.exclude_list, {19,26,33,38}, _xlpm.current_month_idx, MONTH(TODAY()), _xlpm.month_names, {"ינואר","פברואר","מרץ","אפריל","מאי","יוני","יולי","אוגוסט","ספטמבר","אוקטובר","נובמבר","דצמבר"}, _xlpm.target, 350, _xlpm.apartment, B13, _xlpm.payments, E13:P13, IF(ISNUMBER(MATCH(_xlpm.apartment, _xlpm.exclude_list, 0)), "", _xlfn.LET(_xlpm.debt_list, _xlfn.MAP(_xlfn.SEQUENCE(1, 12), _xlpm.month_names, _xlpm.payments, _xlfn.LAMBDA(_xlpm.idx,_xlpm.m_name,_xlpm.p_val, IF(_xlpm.idx > _xlpm.current_month_idx, "", IF(OR(ISBLANK(_xlpm.p_val), _xlpm.p_val = ""), _xlpm.m_name & " (חוב " & _xlpm.target & ")", IF(_xlpm.p_val < _xlpm.target, _xlpm.m_name & " (חוב " & (_xlpm.target - _xlpm.p_val) & ")", ""))))), _xlpm.summary, _xlfn.TEXTJOIN(", ", TRUE, _xlpm.debt_list), IF(_xlpm.summary <> "", "דירה " & _xlpm.apartment & " - " & _xlpm.summary, ""))))}
B14: 13 | C14: בכר | E14: 350 | F14: 350 | G14: 350 | H14: 350 | X14: {=_xlfn.LET(_xlpm.exclude_list, {19,26,33,38}, _xlpm.current_month_idx, MONTH(TODAY()), _xlpm.month_names, {"ינואר","פברואר","מרץ","אפריל","מאי","יוני","יולי","אוגוסט","ספטמבר","אוקטובר","נובמבר","דצמבר"}, _xlpm.target, 350, _xlpm.apartment, B14, _xlpm.payments, E14:P14, IF(ISNUMBER(MATCH(_xlpm.apartment, _xlpm.exclude_list, 0)), "", _xlfn.LET(_xlpm.debt_list, _xlfn.MAP(_xlfn.SEQUENCE(1, 12), _xlpm.month_names, _xlpm.payments, _xlfn.LAMBDA(_xlpm.idx,_xlpm.m_name,_xlpm.p_val, IF(_xlpm.idx > _xlpm.current_month_idx, "", IF(OR(ISBLANK(_xlpm.p_val), _xlpm.p_val = ""), _xlpm.m_name & " (חוב " & _xlpm.target & ")", IF(_xlpm.p_val < _xlpm.target, _xlpm.m_name & " (חוב " & (_xlpm.target - _xlpm.p_val) & ")", ""))))), _xlpm.summary, _xlfn.TEXTJOIN(", ", TRUE, _xlpm.debt_list), IF(_xlpm.summary <> "", "דירה " & _xlpm.apartment & " - " & _xlpm.summary, ""))))}
A15: 4 | B15: 14 | C15: ירין חיים | D15: דניס סיידר | E15: 350 | F15: 350 | G15: 350 | X15: {=_xlfn.LET(_xlpm.exclude_list, {19,26,33,38}, _xlpm.current_month_idx, MONTH(TODAY()), _xlpm.month_names, {"ינואר","פברואר","מרץ","אפריל","מאי","יוני","יולי","אוגוסט","ספטמבר","אוקטובר","נובמבר","דצמבר"}, _xlpm.target, 350, _xlpm.apartment, B15, _xlpm.payments, E15:P15, IF(ISNUMBER(MATCH(_xlpm.apartment, _xlpm.exclude_list, 0)), "", _xlfn.LET(_xlpm.debt_list, _xlfn.MAP(_xlfn.SEQUENCE(1, 12), _xlpm.month_names, _xlpm.payments, _xlfn.LAMBDA(_xlpm.idx,_xlpm.m_name,_xlpm.p_val, IF(_xlpm.idx > _xlpm.current_month_idx, "", IF(OR(ISBLANK(_xlpm.p_val), _xlpm.p_val = ""), _xlpm.m_name & " (חוב " & _xlpm.target & ")", IF(_xlpm.p_val < _xlpm.target, _xlpm.m_name & " (חוב " & (_xlpm.target - _xlpm.p_val) & ")", ""))))), _xlpm.summary, _xlfn.TEXTJOIN(", ", TRUE, _xlpm.debt_list), IF(_xlpm.summary <> "", "דירה " & _xlpm.apartment & " - " & _xlpm.summary, ""))))}
B16: 15 | C16: כהן אביאל | E16: 350 | F16: 350 | G16: 350 | H16: 350 | Q16: 500 | X16: {=_xlfn.LET(_xlpm.exclude_list, {19,26,33,38}, _xlpm.current_month_idx, MONTH(TODAY()), _xlpm.month_names, {"ינואר","פברואר","מרץ","אפריל","מאי","יוני","יולי","אוגוסט","ספטמבר","אוקטובר","נובמבר","דצמבר"}, _xlpm.target, 350, _xlpm.apartment, B16, _xlpm.payments, E16:P16, IF(ISNUMBER(MATCH(_xlpm.apartment, _xlpm.exclude_list, 0)), "", _xlfn.LET(_xlpm.debt_list, _xlfn.MAP(_xlfn.SEQUENCE(1, 12), _xlpm.month_names, _xlpm.payments, _xlfn.LAMBDA(_xlpm.idx,_xlpm.m_name,_xlpm.p_val, IF(_xlpm.idx > _xlpm.current_month_idx, "", IF(OR(ISBLANK(_xlpm.p_val), _xlpm.p_val = ""), _xlpm.m_name & " (חוב " & _xlpm.target & ")", IF(_xlpm.p_val < _xlpm.target, _xlpm.m_name & " (חוב " & (_xlpm.target - _xlpm.p_val) & ")", ""))))), _xlpm.summary, _xlfn.TEXTJOIN(", ", TRUE, _xlpm.debt_list), IF(_xlpm.summary <> "", "דירה " & _xlpm.apartment & " - " & _xlpm.summary, ""))))}
B17: 16 | C17: מקייס סאספורתס | E17: 350 | F17: 350 | G17: 350 | H17: 350 | Q17: 500 | X17: {=_xlfn.LET(_xlpm.exclude_list, {19,26,33,38}, _xlpm.current_month_idx, MONTH(TODAY()), _xlpm.month_names, {"ינואר","פברואר","מרץ","אפריל","מאי","יוני","יולי","אוגוסט","ספטמבר","אוקטובר","נובמבר","דצמבר"}, _xlpm.target, 350, _xlpm.apartment, B17, _xlpm.payments, E17:P17, IF(ISNUMBER(MATCH(_xlpm.apartment, _xlpm.exclude_list, 0)), "", _xlfn.LET(_xlpm.debt_list, _xlfn.MAP(_xlfn.SEQUENCE(1, 12), _xlpm.month_names, _xlpm.payments, _xlfn.LAMBDA(_xlpm.idx,_xlpm.m_name,_xlpm.p_val, IF(_xlpm.idx > _xlpm.current_month_idx, "", IF(OR(ISBLANK(_xlpm.p_val), _xlpm.p_val = ""), _xlpm.m_name & " (חוב " & _xlpm.target & ")", IF(_xlpm.p_val < _xlpm.target, _xlpm.m_name & " (חוב " & (_xlpm.target - _xlpm.p_val) & ")", ""))))), _xlpm.summary, _xlfn.TEXTJOIN(", ", TRUE, _xlpm.debt_list), IF(_xlpm.summary <> "", "דירה " & _xlpm.apartment & " - " & _xlpm.summary, ""))))}
B18: 17 | C18: גבי שובל | E18: 350 | F18: 350 | G18: 350 | Q18: 500 | X18: {=_xlfn.LET(_xlpm.exclude_list, {19,26,33,38}, _xlpm.current_month_idx, MONTH(TODAY()), _xlpm.month_names, {"ינואר","פברואר","מרץ","אפריל","מאי","יוני","יולי","אוגוסט","ספטמבר","אוקטובר","נובמבר","דצמבר"}, _xlpm.target, 350, _xlpm.apartment, B18, _xlpm.payments, E18:P18, IF(ISNUMBER(MATCH(_xlpm.apartment, _xlpm.exclude_list, 0)), "", _xlfn.LET(_xlpm.debt_list, _xlfn.MAP(_xlfn.SEQUENCE(1, 12), _xlpm.month_names, _xlpm.payments, _xlfn.LAMBDA(_xlpm.idx,_xlpm.m_name,_xlpm.p_val, IF(_xlpm.idx > _xlpm.current_month_idx, "", IF(OR(ISBLANK(_xlpm.p_val), _xlpm.p_val = ""), _xlpm.m_name & " (חוב " & _xlpm.target & ")", IF(_xlpm.p_val < _xlpm.target, _xlpm.m_name & " (חוב " & (_xlpm.target - _xlpm.p_val) & ")", ""))))), _xlpm.summary, _xlfn.TEXTJOIN(", ", TRUE, _xlpm.debt_list), IF(_xlpm.summary <> "", "דירה " & _xlpm.apartment & " - " & _xlpm.summary, ""))))}
B19: 18 | C19: מישייב רגינה / לגסה סיטוטאו | D19: רזניק | E19: 350 | F19: 350 | G19: 350 | H19: 350 | Q19: 500 | X19: {=_xlfn.LET(_xlpm.exclude_list, {19,26,33,38}, _xlpm.current_month_idx, MONTH(TODAY()), _xlpm.month_names, {"ינואר","פברואר","מרץ","אפריל","מאי","יוני","יולי","אוגוסט","ספטמבר","אוקטובר","נובמבר","דצמבר"}, _xlpm.target, 350, _xlpm.apartment, B19, _xlpm.payments, E19:P19, IF(ISNUMBER(MATCH(_xlpm.apartment, _xlpm.exclude_list, 0)), "", _xlfn.LET(_xlpm.debt_list, _xlfn.MAP(_xlfn.SEQUENCE(1, 12), _xlpm.month_names, _xlpm.payments, _xlfn.LAMBDA(_xlpm.idx,_xlpm.m_name,_xlpm.p_val, IF(_xlpm.idx > _xlpm.current_month_idx, "", IF(OR(ISBLANK(_xlpm.p_val), _xlpm.p_val = ""), _xlpm.m_name & " (חוב " & _xlpm.target & ")", IF(_xlpm.p_val < _xlpm.target, _xlpm.m_name & " (חוב " & (_xlpm.target - _xlpm.p_val) & ")", ""))))), _xlpm.summary, _xlfn.TEXTJOIN(", ", TRUE, _xlpm.debt_list), IF(_xlpm.summary <> "", "דירה " & _xlpm.apartment & " - " & _xlpm.summary, ""))))}
A20: 5 | B20: 19 | C20: פקרסקי | Q20: 350 | X20: {=_xlfn.LET(_xlpm.exclude_list, {19,26,33,38}, _xlpm.current_month_idx, MONTH(TODAY()), _xlpm.month_names, {"ינואר","פברואר","מרץ","אפריל","מאי","יוני","יולי","אוגוסט","ספטמבר","אוקטובר","נובמבר","דצמבר"}, _xlpm.target, 350, _xlpm.apartment, B20, _xlpm.payments, E20:P20, IF(ISNUMBER(MATCH(_xlpm.apartment, _xlpm.exclude_list, 0)), "", _xlfn.LET(_xlpm.debt_list, _xlfn.MAP(_xlfn.SEQUENCE(1, 12), _xlpm.month_names, _xlpm.payments, _xlfn.LAMBDA(_xlpm.idx,_xlpm.m_name,_xlpm.p_val, IF(_xlpm.idx > _xlpm.current_month_idx, "", IF(OR(ISBLANK(_xlpm.p_val), _xlpm.p_val = ""), _xlpm.m_name & " (חוב " & _xlpm.target & ")", IF(_xlpm.p_val < _xlpm.target, _xlpm.m_name & " (חוב " & (_xlpm.target - _xlpm.p_val) & ")", ""))))), _xlpm.summary, _xlfn.TEXTJOIN(", ", TRUE, _xlpm.debt_list), IF(_xlpm.summary <> "", "דירה " & _xlpm.apartment & " - " & _xlpm.summary, ""))))}
B21: 20 | C21: פרחי נדב שי | E21: 350 | F21: 350 | G21: 350 | H21: 350 | X21: {=_xlfn.LET(_xlpm.exclude_list, {19,26,33,38}, _xlpm.current_month_idx, MONTH(TODAY()), _xlpm.month_names, {"ינואר","פברואר","מרץ","אפריל","מאי","יוני","יולי","אוגוסט","ספטמבר","אוקטובר","נובמבר","דצמבר"}, _xlpm.target, 350, _xlpm.apartment, B21, _xlpm.payments, E21:P21, IF(ISNUMBER(MATCH(_xlpm.apartment, _xlpm.exclude_list, 0)), "", _xlfn.LET(_xlpm.debt_list, _xlfn.MAP(_xlfn.SEQUENCE(1, 12), _xlpm.month_names, _xlpm.payments, _xlfn.LAMBDA(_xlpm.idx,_xlpm.m_name,_xlpm.p_val, IF(_xlpm.idx > _xlpm.current_month_idx, "", IF(OR(ISBLANK(_xlpm.p_val), _xlpm.p_val = ""), _xlpm.m_name & " (חוב " & _xlpm.target & ")", IF(_xlpm.p_val < _xlpm.target, _xlpm.m_name & " (חוב " & (_xlpm.target - _xlpm.p_val) & ")", ""))))), _xlpm.summary, _xlfn.TEXTJOIN(", ", TRUE, _xlpm.debt_list), IF(_xlpm.summary <> "", "דירה " & _xlpm.apartment & " - " & _xlpm.summary, ""))))}
B22: 21 | C22: סימקין טרוסטיאני | E22: 350 | F22: 350 | G22: 350 | H22: 350 | Q22: 500 | X22: {=_xlfn.LET(_xlpm.exclude_list, {19,26,33,38}, _xlpm.current_month_idx, MONTH(TODAY()), _xlpm.month_names, {"ינואר","פברואר","מרץ","אפריל","מאי","יוני","יולי","אוגוסט","ספטמבר","אוקטובר","נובמבר","דצמבר"}, _xlpm.target, 350, _xlpm.apartment, B22, _xlpm.payments, E22:P22, IF(ISNUMBER(MATCH(_xlpm.apartment, _xlpm.exclude_list, 0)), "", _xlfn.LET(_xlpm.debt_list, _xlfn.MAP(_xlfn.SEQUENCE(1, 12), _xlpm.month_names, _xlpm.payments, _xlfn.LAMBDA(_xlpm.idx,_xlpm.m_name,_xlpm.p_val, IF(_xlpm.idx > _xlpm.current_month_idx, "", IF(OR(ISBLANK(_xlpm.p_val), _xlpm.p_val = ""), _xlpm.m_name & " (חוב " & _xlpm.target & ")", IF(_xlpm.p_val < _xlpm.target, _xlpm.m_name & " (חוב " & (_xlpm.target - _xlpm.p_val) & ")", ""))))), _xlpm.summary, _xlfn.TEXTJOIN(", ", TRUE, _xlpm.debt_list), IF(_xlpm.summary <> "", "דירה " & _xlpm.apartment & " - " & _xlpm.summary, ""))))}
B23: 22 | C23: סוזאנה שושנה | E23: 350 | F23: 350 | G23: 350 | H23: 350 | Q23: 200 | X23: {=_xlfn.LET(_xlpm.exclude_list, {19,26,33,38}, _xlpm.current_month_idx, MONTH(TODAY()), _xlpm.month_names, {"ינואר","פברואר","מרץ","אפריל","מאי","יוני","יולי","אוגוסט","ספטמבר","אוקטובר","נובמבר","דצמבר"}, _xlpm.target, 350, _xlpm.apartment, B23, _xlpm.payments, E23:P23, IF(ISNUMBER(MATCH(_xlpm.apartment, _xlpm.exclude_list, 0)), "", _xlfn.LET(_xlpm.debt_list, _xlfn.MAP(_xlfn.SEQUENCE(1, 12), _xlpm.month_names, _xlpm.payments, _xlfn.LAMBDA(_xlpm.idx,_xlpm.m_name,_xlpm.p_val, IF(_xlpm.idx > _xlpm.current_month_idx, "", IF(OR(ISBLANK(_xlpm.p_val), _xlpm.p_val = ""), _xlpm.m_name & " (חוב " & _xlpm.target & ")", IF(_xlpm.p_val < _xlpm.target, _xlpm.m_name & " (חוב " & (_xlpm.target - _xlpm.p_val) & ")", ""))))), _xlpm.summary, _xlfn.TEXTJOIN(", ", TRUE, _xlpm.debt_list), IF(_xlpm.summary <> "", "דירה " & _xlpm.apartment & " - " & _xlpm.summary, ""))))}
B24: 23 | C24: ממן אושרי | E24: 350 | F24: 350 | G24: 350 | H24: 350 | Q24: 500 | X24: {=_xlfn.LET(_xlpm.exclude_list, {19,26,33,38}, _xlpm.current_month_idx, MONTH(TODAY()), _xlpm.month_names, {"ינואר","פברואר","מרץ","אפריל","מאי","יוני","יולי","אוגוסט","ספטמבר","אוקטובר","נובמבר","דצמבר"}, _xlpm.target, 350, _xlpm.apartment, B24, _xlpm.payments, E24:P24, IF(ISNUMBER(MATCH(_xlpm.apartment, _xlpm.exclude_list, 0)), "", _xlfn.LET(_xlpm.debt_list, _xlfn.MAP(_xlfn.SEQUENCE(1, 12), _xlpm.month_names, _xlpm.payments, _xlfn.LAMBDA(_xlpm.idx,_xlpm.m_name,_xlpm.p_val, IF(_xlpm.idx > _xlpm.current_month_idx, "", IF(OR(ISBLANK(_xlpm.p_val), _xlpm.p_val = ""), _xlpm.m_name & " (חוב " & _xlpm.target & ")", IF(_xlpm.p_val < _xlpm.target, _xlpm.m_name & " (חוב " & (_xlpm.target - _xlpm.p_val) & ")", ""))))), _xlpm.summary, _xlfn.TEXTJOIN(", ", TRUE, _xlpm.debt_list), IF(_xlpm.summary <> "", "דירה " & _xlpm.apartment & " - " & _xlpm.summary, ""))))}
A25: 6 | B25: 24 | C25: לב משה | E25: 350 | F25: 350 | G25: 350 | H25: 350 | Q25: 500 | X25: {=_xlfn.LET(_xlpm.exclude_list, {19,26,33,38}, _xlpm.current_month_idx, MONTH(TODAY()), _xlpm.month_names, {"ינואר","פברואר","מרץ","אפריל","מאי","יוני","יולי","אוגוסט","ספטמבר","אוקטובר","נובמבר","דצמבר"}, _xlpm.target, 350, _xlpm.apartment, B25, _xlpm.payments, E25:P25, IF(ISNUMBER(MATCH(_xlpm.apartment, _xlpm.exclude_list, 0)), "", _xlfn.LET(_xlpm.debt_list, _xlfn.MAP(_xlfn.SEQUENCE(1, 12), _xlpm.month_names, _xlpm.payments, _xlfn.LAMBDA(_xlpm.idx,_xlpm.m_name,_xlpm.p_val, IF(_xlpm.idx > _xlpm.current_month_idx, "", IF(OR(ISBLANK(_xlpm.p_val), _xlpm.p_val = ""), _xlpm.m_name & " (חוב " & _xlpm.target & ")", IF(_xlpm.p_val < _xlpm.target, _xlpm.m_name & " (חוב " & (_xlpm.target - _xlpm.p_val) & ")", ""))))), _xlpm.summary, _xlfn.TEXTJOIN(", ", TRUE, _xlpm.debt_list), IF(_xlpm.summary <> "", "דירה " & _xlpm.apartment & " - " & _xlpm.summary, ""))))}
B26: 25 | C26: דון דז'נשבילי / כחלון שלו | D26: בן לולו מרדכי | E26: 350 | F26: 350 | G26: 350 | H26: 350 | Q26: 500 | X26: {=_xlfn.LET(_xlpm.exclude_list, {19,26,33,38}, _xlpm.current_month_idx, MONTH(TODAY()), _xlpm.month_names, {"ינואר","פברואר","מרץ","אפריל","מאי","יוני","יולי","אוגוסט","ספטמבר","אוקטובר","נובמבר","דצמבר"}, _xlpm.target, 350, _xlpm.apartment, B26, _xlpm.payments, E26:P26, IF(ISNUMBER(MATCH(_xlpm.apartment, _xlpm.exclude_list, 0)), "", _xlfn.LET(_xlpm.debt_list, _xlfn.MAP(_xlfn.SEQUENCE(1, 12), _xlpm.month_names, _xlpm.payments, _xlfn.LAMBDA(_xlpm.idx,_xlpm.m_name,_xlpm.p_val, IF(_xlpm.idx > _xlpm.current_month_idx, "", IF(OR(ISBLANK(_xlpm.p_val), _xlpm.p_val = ""), _xlpm.m_name & " (חוב " & _xlpm.target & ")", IF(_xlpm.p_val < _xlpm.target, _xlpm.m_name & " (חוב " & (_xlpm.target - _xlpm.p_val) & ")", ""))))), _xlpm.summary, _xlfn.TEXTJOIN(", ", TRUE, _xlpm.debt_list), IF(_xlpm.summary <> "", "דירה " & _xlpm.apartment & " - " & _xlpm.summary, ""))))}
B27: 26 | C27: שוורץ | Q27: 500 | X27: {=_xlfn.LET(_xlpm.exclude_list, {19,26,33,38}, _xlpm.current_month_idx, MONTH(TODAY()), _xlpm.month_names, {"ינואר","פברואר","מרץ","אפריל","מאי","יוני","יולי","אוגוסט","ספטמבר","אוקטובר","נובמבר","דצמבר"}, _xlpm.target, 350, _xlpm.apartment, B27, _xlpm.payments, E27:P27, IF(ISNUMBER(MATCH(_xlpm.apartment, _xlpm.exclude_list, 0)), "", _xlfn.LET(_xlpm.debt_list, _xlfn.MAP(_xlfn.SEQUENCE(1, 12), _xlpm.month_names, _xlpm.payments, _xlfn.LAMBDA(_xlpm.idx,_xlpm.m_name,_xlpm.p_val, IF(_xlpm.idx > _xlpm.current_month_idx, "", IF(OR(ISBLANK(_xlpm.p_val), _xlpm.p_val = ""), _xlpm.m_name & " (חוב " & _xlpm.target & ")", IF(_xlpm.p_val < _xlpm.target, _xlpm.m_name & " (חוב " & (_xlpm.target - _xlpm.p_val) & ")", ""))))), _xlpm.summary, _xlfn.TEXTJOIN(", ", TRUE, _xlpm.debt_list), IF(_xlpm.summary <> "", "דירה " & _xlpm.apartment & " - " & _xlpm.summary, ""))))}
B28: 27 | C28: אליזבט בינשטוק | E28: 350 | F28: 350 | G28: 350 | H28: 350 | Q28: 500 | S28: 4696863 | X28: {=_xlfn.LET(_xlpm.exclude_list, {19,26,33,38}, _xlpm.current_month_idx, MONTH(TODAY()), _xlpm.month_names, {"ינואר","פברואר","מרץ","אפריל","מאי","יוני","יולי","אוגוסט","ספטמבר","אוקטובר","נובמבר","דצמבר"}, _xlpm.target, 350, _xlpm.apartment, B28, _xlpm.payments, E28:P28, IF(ISNUMBER(MATCH(_xlpm.apartment, _xlpm.exclude_list, 0)), "", _xlfn.LET(_xlpm.debt_list, _xlfn.MAP(_xlfn.SEQUENCE(1, 12), _xlpm.month_names, _xlpm.payments, _xlfn.LAMBDA(_xlpm.idx,_xlpm.m_name,_xlpm.p_val, IF(_xlpm.idx > _xlpm.current_month_idx, "", IF(OR(ISBLANK(_xlpm.p_val), _xlpm.p_val = ""), _xlpm.m_name & " (חוב " & _xlpm.target & ")", IF(_xlpm.p_val < _xlpm.target, _xlpm.m_name & " (חוב " & (_xlpm.target - _xlpm.p_val) & ")", ""))))), _xlpm.summary, _xlfn.TEXTJOIN(", ", TRUE, _xlpm.debt_list), IF(_xlpm.summary <> "", "דירה " & _xlpm.apartment & " - " & _xlpm.summary, ""))))}
B29: 28 | C29: וולושין אלכסנדר | E29: 350 | F29: 350 | G29: 350 | H29: 350 | Q29: 500 | S29: 4832180 | X29: {=_xlfn.LET(_xlpm.exclude_list, {19,26,33,38}, _xlpm.current_month_idx, MONTH(TODAY()), _xlpm.month_names, {"ינואר","פברואר","מרץ","אפריל","מאי","יוני","יולי","אוגוסט","ספטמבר","אוקטובר","נובמבר","דצמבר"}, _xlpm.target, 350, _xlpm.apartment, B29, _xlpm.payments, E29:P29, IF(ISNUMBER(MATCH(_xlpm.apartment, _xlpm.exclude_list, 0)), "", _xlfn.LET(_xlpm.debt_list, _xlfn.MAP(_xlfn.SEQUENCE(1, 12), _xlpm.month_names, _xlpm.payments, _xlfn.LAMBDA(_xlpm.idx,_xlpm.m_name,_xlpm.p_val, IF(_xlpm.idx > _xlpm.current_month_idx, "", IF(OR(ISBLANK(_xlpm.p_val), _xlpm.p_val = ""), _xlpm.m_name & " (חוב " & _xlpm.target & ")", IF(_xlpm.p_val < _xlpm.target, _xlpm.m_name & " (חוב " & (_xlpm.target - _xlpm.p_val) & ")", ""))))), _xlpm.summary, _xlfn.TEXTJOIN(", ", TRUE, _xlpm.debt_list), IF(_xlpm.summary <> "", "דירה " & _xlpm.apartment & " - " & _xlpm.summary, ""))))}
A30: 7 | B30: 29 | C30: קשר ספורט | D30: לואי הזימה | E30: 350 | F30: 350 | G30: 350 | H30: 350 | I30: 350 | J30: 350 | Q30: 500 | X30: {=_xlfn.LET(_xlpm.exclude_list, {19,26,33,38}, _xlpm.current_month_idx, MONTH(TODAY()), _xlpm.month_names, {"ינואר","פברואר","מרץ","אפריל","מאי","יוני","יולי","אוגוסט","ספטמבר","אוקטובר","נובמבר","דצמבר"}, _xlpm.target, 350, _xlpm.apartment, B30, _xlpm.payments, E30:P30, IF(ISNUMBER(MATCH(_xlpm.apartment, _xlpm.exclude_list, 0)), "", _xlfn.LET(_xlpm.debt_list, _xlfn.MAP(_xlfn.SEQUENCE(1, 12), _xlpm.month_names, _xlpm.payments, _xlfn.LAMBDA(_xlpm.idx,_xlpm.m_name,_xlpm.p_val, IF(_xlpm.idx > _xlpm.current_month_idx, "", IF(OR(ISBLANK(_xlpm.p_val), _xlpm.p_val = ""), _xlpm.m_name & " (חוב " & _xlpm.target & ")", IF(_xlpm.p_val < _xlpm.target, _xlpm.m_name & " (חוב " & (_xlpm.target - _xlpm.p_val) & ")", ""))))), _xlpm.summary, _xlfn.TEXTJOIN(", ", TRUE, _xlpm.debt_list), IF(_xlpm.summary <> "", "דירה " & _xlpm.apartment & " - " & _xlpm.summary, ""))))}
B31: 30 | C31: מזרחי / אסולין יעקב | E31: 350 | F31: 350 | G31: 350 | H31: 350 | Q31: 500 | X31: {=_xlfn.LET(_xlpm.exclude_list, {19,26,33,38}, _xlpm.current_month_idx, MONTH(TODAY()), _xlpm.month_names, {"ינואר","פברואר","מרץ","אפריל","מאי","יוני","יולי","אוגוסט","ספטמבר","אוקטובר","נובמבר","דצמבר"}, _xlpm.target, 350, _xlpm.apartment, B31, _xlpm.payments, E31:P31, IF(ISNUMBER(MATCH(_xlpm.apartment, _xlpm.exclude_list, 0)), "", _xlfn.LET(_xlpm.debt_list, _xlfn.MAP(_xlfn.SEQUENCE(1, 12), _xlpm.month_names, _xlpm.payments, _xlfn.LAMBDA(_xlpm.idx,_xlpm.m_name,_xlpm.p_val, IF(_xlpm.idx > _xlpm.current_month_idx, "", IF(OR(ISBLANK(_xlpm.p_val), _xlpm.p_val = ""), _xlpm.m_name & " (חוב " & _xlpm.target & ")", IF(_xlpm.p_val < _xlpm.target, _xlpm.m_name & " (חוב " & (_xlpm.target - _xlpm.p_val) & ")", ""))))), _xlpm.summary, _xlfn.TEXTJOIN(", ", TRUE, _xlpm.debt_list), IF(_xlpm.summary <> "", "דירה " & _xlpm.apartment & " - " & _xlpm.summary, ""))))}
B32: 31 | C32: זאדה הודיה | E32: 350 | F32: 350 | G32: 350 | H32: 350 | Q32: 500 | X32: {=_xlfn.LET(_xlpm.exclude_list, {19,26,33,38}, _xlpm.current_month_idx, MONTH(TODAY()), _xlpm.month_names, {"ינואר","פברואר","מרץ","אפריל","מאי","יוני","יולי","אוגוסט","ספטמבר","אוקטובר","נובמבר","דצמבר"}, _xlpm.target, 350, _xlpm.apartment, B32, _xlpm.payments, E32:P32, IF(ISNUMBER(MATCH(_xlpm.apartment, _xlpm.exclude_list, 0)), "", _xlfn.LET(_xlpm.debt_list, _xlfn.MAP(_xlfn.SEQUENCE(1, 12), _xlpm.month_names, _xlpm.payments, _xlfn.LAMBDA(_xlpm.idx,_xlpm.m_name,_xlpm.p_val, IF(_xlpm.idx > _xlpm.current_month_idx, "", IF(OR(ISBLANK(_xlpm.p_val), _xlpm.p_val = ""), _xlpm.m_name & " (חוב " & _xlpm.target & ")", IF(_xlpm.p_val < _xlpm.target, _xlpm.m_name & " (חוב " & (_xlpm.target - _xlpm.p_val) & ")", ""))))), _xlpm.summary, _xlfn.TEXTJOIN(", ", TRUE, _xlpm.debt_list), IF(_xlpm.summary <> "", "דירה " & _xlpm.apartment & " - " & _xlpm.summary, ""))))}
B33: 32 | C33: ריזק | E33: 350 | F33: 350 | G33: 350 | H33: 350 | Q33: 500 | S33: 4684245 | X33: {=_xlfn.LET(_xlpm.exclude_list, {19,26,33,38}, _xlpm.current_month_idx, MONTH(TODAY()), _xlpm.month_names, {"ינואר","פברואר","מרץ","אפריל","מאי","יוני","יולי","אוגוסט","ספטמבר","אוקטובר","נובמבר","דצמבר"}, _xlpm.target, 350, _xlpm.apartment, B33, _xlpm.payments, E33:P33, IF(ISNUMBER(MATCH(_xlpm.apartment, _xlpm.exclude_list, 0)), "", _xlfn.LET(_xlpm.debt_list, _xlfn.MAP(_xlfn.SEQUENCE(1, 12), _xlpm.month_names, _xlpm.payments, _xlfn.LAMBDA(_xlpm.idx,_xlpm.m_name,_xlpm.p_val, IF(_xlpm.idx > _xlpm.current_month_idx, "", IF(OR(ISBLANK(_xlpm.p_val), _xlpm.p_val = ""), _xlpm.m_name & " (חוב " & _xlpm.target & ")", IF(_xlpm.p_val < _xlpm.target, _xlpm.m_name & " (חוב " & (_xlpm.target - _xlpm.p_val) & ")", ""))))), _xlpm.summary, _xlfn.TEXTJOIN(", ", TRUE, _xlpm.debt_list), IF(_xlpm.summary <> "", "דירה " & _xlpm.apartment & " - " & _xlpm.summary, ""))))}
B34: 33 | C34: וילצר | Q34: 500 | X34: {=_xlfn.LET(_xlpm.exclude_list, {19,26,33,38}, _xlpm.current_month_idx, MONTH(TODAY()), _xlpm.month_names, {"ינואר","פברואר","מרץ","אפריל","מאי","יוני","יולי","אוגוסט","ספטמבר","אוקטובר","נובמבר","דצמבר"}, _xlpm.target, 350, _xlpm.apartment, B34, _xlpm.payments, E34:P34, IF(ISNUMBER(MATCH(_xlpm.apartment, _xlpm.exclude_list, 0)), "", _xlfn.LET(_xlpm.debt_list, _xlfn.MAP(_xlfn.SEQUENCE(1, 12), _xlpm.month_names, _xlpm.payments, _xlfn.LAMBDA(_xlpm.idx,_xlpm.m_name,_xlpm.p_val, IF(_xlpm.idx > _xlpm.current_month_idx, "", IF(OR(ISBLANK(_xlpm.p_val), _xlpm.p_val = ""), _xlpm.m_name & " (חוב " & _xlpm.target & ")", IF(_xlpm.p_val < _xlpm.target, _xlpm.m_name & " (חוב " & (_xlpm.target - _xlpm.p_val) & ")", ""))))), _xlpm.summary, _xlfn.TEXTJOIN(", ", TRUE, _xlpm.debt_list), IF(_xlpm.summary <> "", "דירה " & _xlpm.apartment & " - " & _xlpm.summary, ""))))}
A35: 8 | B35: 34 | C35: סיגלוב דימיטרי | E35: 350 | F35: 350 | G35: 350 | H35: 350 | Q35: 500 | X35: {=_xlfn.LET(_xlpm.exclude_list, {19,26,33,38}, _xlpm.current_month_idx, MONTH(TODAY()), _xlpm.month_names, {"ינואר","פברואר","מרץ","אפריל","מאי","יוני","יולי","אוגוסט","ספטמבר","אוקטובר","נובמבר","דצמבר"}, _xlpm.target, 350, _xlpm.apartment, B35, _xlpm.payments, E35:P35, IF(ISNUMBER(MATCH(_xlpm.apartment, _xlpm.exclude_list, 0)), "", _xlfn.LET(_xlpm.debt_list, _xlfn.MAP(_xlfn.SEQUENCE(1, 12), _xlpm.month_names, _xlpm.payments, _xlfn.LAMBDA(_xlpm.idx,_xlpm.m_name,_xlpm.p_val, IF(_xlpm.idx > _xlpm.current_month_idx, "", IF(OR(ISBLANK(_xlpm.p_val), _xlpm.p_val = ""), _xlpm.m_name & " (חוב " & _xlpm.target & ")", IF(_xlpm.p_val < _xlpm.target, _xlpm.m_name & " (חוב " & (_xlpm.target - _xlpm.p_val) & ")", ""))))), _xlpm.summary, _xlfn.TEXTJOIN(", ", TRUE, _xlpm.debt_list), IF(_xlpm.summary <> "", "דירה " & _xlpm.apartment & " - " & _xlpm.summary, ""))))}
B36: 35 | C36: גלמן אירינה | E36: 350 | F36: 350 | G36: 350 | H36: 350 | Q36: 500 | S36: 4775354 | X36: {=_xlfn.LET(_xlpm.exclude_list, {19,26,33,38}, _xlpm.current_month_idx, MONTH(TODAY()), _xlpm.month_names, {"ינואר","פברואר","מרץ","אפריל","מאי","יוני","יולי","אוגוסט","ספטמבר","אוקטובר","נובמבר","דצמבר"}, _xlpm.target, 350, _xlpm.apartment, B36, _xlpm.payments, E36:P36, IF(ISNUMBER(MATCH(_xlpm.apartment, _xlpm.exclude_list, 0)), "", _xlfn.LET(_xlpm.debt_list, _xlfn.MAP(_xlfn.SEQUENCE(1, 12), _xlpm.month_names, _xlpm.payments, _xlfn.LAMBDA(_xlpm.idx,_xlpm.m_name,_xlpm.p_val, IF(_xlpm.idx > _xlpm.current_month_idx, "", IF(OR(ISBLANK(_xlpm.p_val), _xlpm.p_val = ""), _xlpm.m_name & " (חוב " & _xlpm.target & ")", IF(_xlpm.p_val < _xlpm.target, _xlpm.m_name & " (חוב " & (_xlpm.target - _xlpm.p_val) & ")", ""))))), _xlpm.summary, _xlfn.TEXTJOIN(", ", TRUE, _xlpm.debt_list), IF(_xlpm.summary <> "", "דירה " & _xlpm.apartment & " - " & _xlpm.summary, ""))))}
B37: 36 | C37: יונה חמד | E37: 350 | F37: 350 | G37: 350 | H37: 350 | X37: {=_xlfn.LET(_xlpm.exclude_list, {19,26,33,38}, _xlpm.current_month_idx, MONTH(TODAY()), _xlpm.month_names, {"ינואר","פברואר","מרץ","אפריל","מאי","יוני","יולי","אוגוסט","ספטמבר","אוקטובר","נובמבר","דצמבר"}, _xlpm.target, 350, _xlpm.apartment, B37, _xlpm.payments, E37:P37, IF(ISNUMBER(MATCH(_xlpm.apartment, _xlpm.exclude_list, 0)), "", _xlfn.LET(_xlpm.debt_list, _xlfn.MAP(_xlfn.SEQUENCE(1, 12), _xlpm.month_names, _xlpm.payments, _xlfn.LAMBDA(_xlpm.idx,_xlpm.m_name,_xlpm.p_val, IF(_xlpm.idx > _xlpm.current_month_idx, "", IF(OR(ISBLANK(_xlpm.p_val), _xlpm.p_val = ""), _xlpm.m_name & " (חוב " & _xlpm.target & ")", IF(_xlpm.p_val < _xlpm.target, _xlpm.m_name & " (חוב " & (_xlpm.target - _xlpm.p_val) & ")", ""))))), _xlpm.summary, _xlfn.TEXTJOIN(", ", TRUE, _xlpm.debt_list), IF(_xlpm.summary <> "", "דירה " & _xlpm.apartment & " - " & _xlpm.summary, ""))))}
B38: 37 | C38: חיון / ספיר אלון / מהרי פקדה | D38: קליגר אדוארד | E38: 350 | F38: 350 | G38: 350 | X38: {=_xlfn.LET(_xlpm.exclude_list, {19,26,33,38}, _xlpm.current_month_idx, MONTH(TODAY()), _xlpm.month_names, {"ינואר","פברואר","מרץ","אפריל","מאי","יוני","יולי","אוגוסט","ספטמבר","אוקטובר","נובמבר","דצמבר"}, _xlpm.target, 350, _xlpm.apartment, B38, _xlpm.payments, E38:P38, IF(ISNUMBER(MATCH(_xlpm.apartment, _xlpm.exclude_list, 0)), "", _xlfn.LET(_xlpm.debt_list, _xlfn.MAP(_xlfn.SEQUENCE(1, 12), _xlpm.month_names, _xlpm.payments, _xlfn.LAMBDA(_xlpm.idx,_xlpm.m_name,_xlpm.p_val, IF(_xlpm.idx > _xlpm.current_month_idx, "", IF(OR(ISBLANK(_xlpm.p_val), _xlpm.p_val = ""), _xlpm.m_name & " (חוב " & _xlpm.target & ")", IF(_xlpm.p_val < _xlpm.target, _xlpm.m_name & " (חוב " & (_xlpm.target - _xlpm.p_val) & ")", ""))))), _xlpm.summary, _xlfn.TEXTJOIN(", ", TRUE, _xlpm.debt_list), IF(_xlpm.summary <> "", "דירה " & _xlpm.apartment & " - " & _xlpm.summary, ""))))}
B39: 38 | C39: ברכה | X39: {=_xlfn.LET(_xlpm.exclude_list, {19,26,33,38}, _xlpm.current_month_idx, MONTH(TODAY()), _xlpm.month_names, {"ינואר","פברואר","מרץ","אפריל","מאי","יוני","יולי","אוגוסט","ספטמבר","אוקטובר","נובמבר","דצמבר"}, _xlpm.target, 350, _xlpm.apartment, B39, _xlpm.payments, E39:P39, IF(ISNUMBER(MATCH(_xlpm.apartment, _xlpm.exclude_list, 0)), "", _xlfn.LET(_xlpm.debt_list, _xlfn.MAP(_xlfn.SEQUENCE(1, 12), _xlpm.month_names, _xlpm.payments, _xlfn.LAMBDA(_xlpm.idx,_xlpm.m_name,_xlpm.p_val, IF(_xlpm.idx > _xlpm.current_month_idx, "", IF(OR(ISBLANK(_xlpm.p_val), _xlpm.p_val = ""), _xlpm.m_name & " (חוב " & _xlpm.target & ")", IF(_xlpm.p_val < _xlpm.target, _xlpm.m_name & " (חוב " & (_xlpm.target - _xlpm.p_val) & ")", ""))))), _xlpm.summary, _xlfn.TEXTJOIN(", ", TRUE, _xlpm.debt_list), IF(_xlpm.summary <> "", "דירה " & _xlpm.apartment & " - " & _xlpm.summary, ""))))}
A40: 9 | B40: 39 | C40: פריידמן נטליה | E40: 350 | F40: 350 | G40: 350 | H40: 350 | Q40: 500 | S40: 4668970 | X40: {=_xlfn.LET(_xlpm.exclude_list, {19,26,33,38}, _xlpm.current_month_idx, MONTH(TODAY()), _xlpm.month_names, {"ינואר","פברואר","מרץ","אפריל","מאי","יוני","יולי","אוגוסט","ספטמבר","אוקטובר","נובמבר","דצמבר"}, _xlpm.target, 350, _xlpm.apartment, B40, _xlpm.payments, E40:P40, IF(ISNUMBER(MATCH(_xlpm.apartment, _xlpm.exclude_list, 0)), "", _xlfn.LET(_xlpm.debt_list, _xlfn.MAP(_xlfn.SEQUENCE(1, 12), _xlpm.month_names, _xlpm.payments, _xlfn.LAMBDA(_xlpm.idx,_xlpm.m_name,_xlpm.p_val, IF(_xlpm.idx > _xlpm.current_month_idx, "", IF(OR(ISBLANK(_xlpm.p_val), _xlpm.p_val = ""), _xlpm.m_name & " (חוב " & _xlpm.target & ")", IF(_xlpm.p_val < _xlpm.target, _xlpm.m_name & " (חוב " & (_xlpm.target - _xlpm.p_val) & ")", ""))))), _xlpm.summary, _xlfn.TEXTJOIN(", ", TRUE, _xlpm.debt_list), IF(_xlpm.summary <> "", "דירה " & _xlpm.apartment & " - " & _xlpm.summary, ""))))}
...

Sheet הוצאות 2026
A1: הוצאה | B1: ינואר 25 | C1: פברואר 25 | D1: מרץ 25 | E1: אפריל 25 | F1: מאי 25 | G1: יוני 25 | H1: יולי 25 | I1: אוגוסט 25 | J1: ספטמבר 25 | K1: אוקטובר 25 | L1: נובמבר 25 | M1: דצמבר 25 | N1: ממוצא חודשי | O1: סה"כ שנתי
A2: יניב אחזקות | B2: 7500 | C2: 7500 | D2: 7500 | E2: 7500 | N2: =AVERAGE(Table2[[#This Row],[ינואר 25]:[דצמבר 25]]) | O2: =SUM(Table2[[#This Row],[ינואר 25]:[דצמבר 25]])
A3: קונה מעליות | B3: 4361.79 | C3: 4361.79 | D3: 4549.48 | E3: 4558.28 | N3: =AVERAGE(Table2[[#This Row],[ינואר 25]:[דצמבר 25]]) | O3: =SUM(Table2[[#This Row],[ינואר 25]:[דצמבר 25]])
A4: חשמל ציבורי | B4: 3545.6 | C4: 3595.06 | D4: 3233.77 | E4: 3353.66 | N4: =AVERAGE(Table2[[#This Row],[ינואר 25]:[דצמבר 25]]) | O4: =SUM(Table2[[#This Row],[ינואר 25]:[דצמבר 25]])
A5: גינון | B5: 1500 | C5: 900 | D5: 900 | E5: 900 | N5: =AVERAGE(Table2[[#This Row],[ינואר 25]:[דצמבר 25]]) | O5: =SUM(Table2[[#This Row],[ינואר 25]:[דצמבר 25]])
A6: ביטוח | B6: 981 | C6: 982 | D6: 979 | E6: 981 | N6: =AVERAGE(Table2[[#This Row],[ינואר 25]:[דצמבר 25]]) | O6: =SUM(Table2[[#This Row],[ינואר 25]:[דצמבר 25]])
A7: ארדן בטיחות | B7: 780.11 | C7: 780.11 | D7: 780.11 | N7: =AVERAGE(Table2[[#This Row],[ינואר 25]:[דצמבר 25]]) | O7: =SUM(Table2[[#This Row],[ינואר 25]:[דצמבר 25]])
A8: פרטנר | B8: 90.77 | C8: 90.77 | D8: 90.77 | E8: 90.77 | N8: =AVERAGE(Table2[[#This Row],[ינואר 25]:[דצמבר 25]]) | O8: =SUM(Table2[[#This Row],[ינואר 25]:[דצמבר 25]])
A9: Novula - מסך טלויזיה | B9: 0 | C9: 0 | D9: =77+74.25 | E9: 77 | N9: =AVERAGE(Table2[[#This Row],[ינואר 25]:[דצמבר 25]]) | O9: =SUM(Table2[[#This Row],[ינואר 25]:[דצמבר 25]])
A10: בזק | B10: 24.57 | C10: 0 | D10: =24.57+24.57 | E10: 24.57 | N10: =AVERAGE(Table2[[#This Row],[ינואר 25]:[דצמבר 25]]) | O10: =SUM(Table2[[#This Row],[ינואר 25]:[דצמבר 25]])
A11: מסלול בנק | B11: 25 | C11: 25 | D11: 25 | E11: 25 | N11: =AVERAGE(Table2[[#This Row],[ינואר 25]:[דצמבר 25]]) | O11: =SUM(Table2[[#This Row],[ינואר 25]:[דצמבר 25]])
A12: עמלות בנק | B12: 14.85 | C12: 14.85 | D12: 24.75 | E12: 26.4 | N12: =AVERAGE(Table2[[#This Row],[ינואר 25]:[דצמבר 25]]) | O12: =SUM(Table2[[#This Row],[ינואר 25]:[דצמבר 25]])
A13: כללי | B13: 606 | C13: =500+700+48.38+177+665+650+350 | D13: 6500
A14: קופה קטנה | B14: ='קופה קטנה'!B43 | C14: ='קופה קטנה'!C43 | D14: ='קופה קטנה'!D43 | E14: ='קופה קטנה'!E43 | F14: ='קופה קטנה'!F43 | G14: ='קופה קטנה'!G43 | H14: ='קופה קטנה'!H43 | I14: ='קופה קטנה'!I43 | ... M14: ='קופה קטנה'!M43
A16: הוצאות שוטף | B16: =SUM(B2:B13) | C16: =SUM(C2:C13) | D16: =SUM(D2:D13) | E16: =SUM(E2:E13) | F16: =SUM(F2:F13) | G16: =SUM(G2:G13) | H16: =SUM(H2:H13) | I16: =SUM(I2:I13) | ... M16: =SUM(M2:M13) | N16: =AVERAGE(Table2[[#This Row],[ינואר 25]:[דצמבר 25]]) | O16: =SUM(Table2[[#This Row],[ינואר 25]:[דצמבר 25]])
A17: הוצאות לא שוטף | B17: =SUM(B14) | C17: =SUM(C14) | D17: =SUM(D14) | E17: =SUM(E14) | F17: =SUM(F14) | G17: =SUM(G14) | H17: =SUM(H14) | I17: =SUM(I14) | ... M17: =SUM(M14) | N17: =AVERAGE(Table2[[#This Row],[ינואר 25]:[דצמבר 25]]) | O17: =SUM(Table2[[#This Row],[ינואר 25]:[דצמבר 25]])
A18: הוצאות סה"כ | B18: =SUM(B16:B17) | C18: =SUM(C16:C17) | D18: =SUM(D16:D17) | E18: =SUM(E16:E17) | F18: =SUM(F16:F17) | G18: =SUM(G16:G17) | H18: =SUM(H16:H17) | I18: =SUM(I16:I17) | ... M18: =SUM(M16:M17) | N18: =AVERAGE(Table2[[#This Row],[ינואר 25]:[דצמבר 25]]) | O18: =SUM(Table2[[#This Row],[ינואר 25]:[דצמבר 25]])
A19: הכנסות שוטף | B19: ='גביה 2026'!E62 | C19: ='גביה 2026'!F62 | D19: ='גביה 2026'!G62 | E19: ='גביה 2026'!H62 | F19: ='גביה 2026'!I62 | G19: ='גביה 2026'!J62 | H19: ='גביה 2026'!K62 | I19: ='גביה 2026'!L62 | ... M19: ='גביה 2026'!P62 | N19: =AVERAGE(Table2[[#This Row],[ינואר 25]:[דצמבר 25]]) | O19: =SUM(Table2[[#This Row],[ינואר 25]:[דצמבר 25]])
A20: יחס שוטף הכנסות/הוצאות | B20: =B16/B19 | C20: =C16/C19 | D20: =D16/D19 | E20: =E16/E19 | F20: =F16/F19 | G20: =G16/G19 | H20: =H16/H19 | I20: =I16/I19 | ... M20: =M16/M19 | N20: =AVERAGE(Table2[[#This Row],[ינואר 25]:[דצמבר 25]]) | O20: =SUM(Table2[[#This Row],[ינואר 25]:[דצמבר 25]])
A23: הערות | B23: בדק מעליות גינון 600 שקל דשן | C23: סידור אבנים משתלבות + משלוח סטרימר נובולה + אנטילופה + גופי תאורה 2 + כבל 20 מטר + צילינדר + ספק מנועל + ממסר למחסום | D23: שיפוץ חדרי מדרגות
A31: חשמל 2025 | B31: 3418.26 | C31: 3709.15 | D31: 3132.7 | E31: 2419.7 | F31: 2815.9 | G31: 2654.16 | H31: 4136.59 | I31: 4659.15 | J31: 3864.61 | K31: 3852.93 | L31: 2405.74 | M31: 2342.94 | N31: =AVERAGE(Table2[[#This Row],[ינואר 25]:[דצמבר 25]]) | O31: =SUM(Table2[[#This Row],[ינואר 25]:[דצמבר 25]])

Sheet Jan26
A1: בנק לאומי |
A2: מס' חשבון : ‏‏ ‎885-37554/82‎
A3: תאריך שמירה/הדפסה: 26/1/2026
A5: היתרה | C5: מסגרת האשראי | E5: נכון לתאריך
A7: ₪ 41,308.48 | C7: ₪ 0.00 | E7: 26.01.26
A11: תנועות בחשבון
A12: תאריך | B12: תאריך ערך | C12: תיאור | D12: אסמכתא | E12: בחובה | F12: בזכות | G12: היתרה בש"ח | H12: תאור מורחב
A13: 46023 | B13: 46023 | C13: בנק הפועלים | D13: 99012 | E13: 0 | F13: 320 | G13: 30014.31 | H13: העברה מאת: ברייב יולי 12-701-000404014 ועד בית
A14: 46023 | B14: 46023 | C14: בנק הפועלים | D14: 99012 | E14: 0 | F14: 700 | G14: 30714.31 | H14: העברה מאת: לגסה סיטוטאו יטא 12-700-000089393 ועד בית
A15: 46023 | B15: 46023 | C15: מהבינלאומי ס-י | D15: 99031 | E15: 0 | F15: 500 | G15: 31214.31 | H15: העברה מאת: וילצר סופיה ו/או 31-007-105949663 קופה קטנה של בוריס (הערת לקוח)
A16: 46023 | B16: 46023 | C16: הוראת קבע | D16: 4873628 | E16: 0 | F16: 350 | G16: 31564.31 | H16: העברה מאת: אליזבט בינשטוק, 10-891-003641132 תשלום בהוראת קבע
A17: 46023 | B17: 46023 | C17: מסלול מורחב | D17: 44924 | E17: 25 | F17: 0 | G17: 31539.31
A18: 46023 | B18: 46023 | C18: עמל.ערוץ יש 9 | D18: 9 | E18: 14.85 | F18: 0 | G18: 31524.46 | H18: סכום החיוב מייצג את מספר התנועות שבוצעו בערוץ ישיר/פקיד. מספר התנועות מופיע בסמוך למלל. סכום העמלה לפעולה הינו כפי המופיע בתעריף העמלות ליחיד/תאגיד ובהתאם להטבות הקיימות ללקוח דהיינו סכום חיוב = מספר תנועות ערוץ פקיד/ישיר כפול תעריף העמלה בחשבון הלקוח
A19: 46023 | B19: 46023 | C19: הע. אינטרנט | D19: 2419 | E19: 606 | F19: 0 | G19: 30918.46 | H19: העברה אל: טיבה בטיחות במעל 12-747-000313530 חשבונית 504979
A20: 46054 | B20: 46054 | C20: בנק הפועלים | D20: 99012 | E20: 0 | F20: 350 | G20: 31268.46 | H20: העברה מאת: רועי ולי-ש 12-700-000616685 ועד בית
A21: 46054 | B21: 46054 | C21: בנק הפועלים | D21: 99012 | E21: 0 | F21: 350 | G21: 31618.46 | H21: העברה מאת: מנגיסטו דג 12-703-000091338 לוועד הבית
A22: 46054 | B22: 46054 | C22: הוראת קבע | D22: 4668970 | E22: 0 | F22: 350 | G22: 31968.46 | H22: העברה מאת: פריידמן נטליה 10-882-044876260 תשלום
A23: 46054 | B23: 46054 | C23: העברה דיגיטל | D23: 86770 | E23: 10266 | F23: 0 | G23: 21702.46 | H23: העברה אל: גלים שה תחזוקה 31-022-000080204 מנוע מפוח האגמית 7
A24: 46113 | B24: 46113 | C24: הפקדת שיק | D24: 53458 | E24: 0 | F24: 320 | G24: 22022.46
A25: 46113 | B25: 46113 | C25: הפקדת שיק | D25: 120988 | E25: 0 | F25: 350 | G25: 22372.46
A26: 46113 | B26: 46113 | C26: הוראת קבע | D26: 4878373 | E26: 0 | F26: 350 | G26: 22722.46 | H26: העברה מאת: גל ברזני, שני ול 10-635-001111123 וועד בית דירה 56
A27: 46143 | B27: 46143 | C27: בנק דיסקונט | D27: 99011 | E27: 0 | F27: 320 | G27: 23042.46 | H27: העברה מאת: אסרף אורטל 11-107-081754738
A28: 46143 | B28: 46143 | C28: בנק אוצר החיל | D28: 99014 | E28: 0 | F28: 350 | G28: 23392.46 | H28: העברה מאת: כחלון שלו ו/או ח 14-350-105236062 וועד בית דירה 25 (הערת לקוח)
A29: 46143 | B29: 46143 | C29: הוראת קבע | D29: 4789577 | E29: 0 | F29: 350 | G29: 23742.46 | H29: העברה מאת: קטרינה שליאק 10-838-002943311 דירה 43 משפחת שליאק
A30: 46174 | B30: 46174 | C30: בנק הפועלים | D30: 99012 | E30: 0 | F30: 350 | G30: 24092.46 | H30: העברה מאת: אל איי הנדסת בטי 12-703-000496840 ועד דירה 57
A31: 46174 | B31: 46174 | C31: הוראת קבע | D31: 4870113 | E31: 0 | F31: 350 | G31: 24442.46 | H31: העברה מאת: היבה ריזק 10-840-002040614 ועד בית דירה 32 קומה 7
A32: 46204 | B32: 46204 | C32: מבנק יהב ס.-י | D32: 99004 | E32: 0 | F32: 420 | G32: 24862.46 | H32: העברה מאת: מנצור אלירן אלבר 04-140-000303334 26וכל 25עבור נוב דצ 12דירה 350ל
A33: 46235 | B33: 46235 | C33: איי.די. אי ח-י | D33: 91456 | E33: 0 | F33: 17503.5 | G33: 42365.96 | H33: העברה מאת: איי.די.אי 20-494-000201250 זיכוי
A34: 46235 | B34: 46235 | C34: בנק הפועלים | D34: 99012 | E34: 0 | F34: 350 | G34: 42715.96 | H34: העברה מאת: סיגלוב דמיטרי או 12-703-000021291 דירה 34 סיגלוב
A35: 46266 | B35: 46266 | C35: בנק הפועלים | D35: 99012 | E35: 0 | F35: 320 | G35: 43035.96 | H35: העברה מאת: אסולין יעק 12-704-000263394 ועד בית
A36: 46266 | B36: 46266 | C36: בנק הפועלים | D36: 99012 | E36: 0 | F36: 350 | G36: 43385.96 | H36: העברה מאת: בייבקוב קו 12-701-000262613 דירה 9
A37: 46266 | B37: 46266 | C37: בנק הפועלים | D37: 99012 | E37: 0 | F37: 350 | G37: 43735.96 | H37: העברה מאת: אל איי הנד 12-703-000496840 ועד דירה 57
... A41: 46266 | B41: 46266 | C41: הוראת קבע | D41: 4899758 | E41: 0 | F41: 350 | G41: 45135.96 | H41: העברה מאת: וולושין אלכסנדר 10-879-057984481 ועד בית
A42: 46327 | B42: 46327 | C42: ש.שלמה חברה-י | D42: 44855 | E42: 981 | F42: 0 | G42: 44154.96
A43: 46327 | B43: 46327 | C43: בנק דיסקונט | D43: 99011 | E43: 0 | F43: 350 | G43: 44504.96 | H43: העברה מאת: סימקין טרוסטיאני 11-097-132698643 ועד הבית - סימקין דירה 21
A44: 46327 | B44: 46327 | C44: בנק דיסקונט | D44: 99011 | E44: 0 | F44: 350 | G44: 44854.96 | H44: העברה מאת: רומנו לינצקי סיו 11-107-075555974
A45: 46327 | B45: 46327 | C45: בנק דיסקונט | D45: 99011 | E45: 0 | F45: 350 | G45: 45204.96 | H45: העברה מאת: שרביט גל,טויזר נ 11-107-205119303 דירה 60
A46: 46327 | B46: 46327 | C46: בנק אוצר החיל | D46: 99014 | E46: 0 | F46: 350 | G46: 45554.96 | H46: העברה מאת: כהן אביאל 14-350-000175551 ועד בית
A47: 46327 | B47: 46327 | C47: בנק אוצר החיל | D47: 99014 | E47: 0 | F47: 350 | G47: 45904.96 | H47: העברה מאת: זלץ ניר ו/או נט 14-362-105079420 העברה לוועד בית
A48: 46327 | B48: 46327 | C48: בנק אוצר החיל | D48: 99014 | E48: 0 | F48: 350 | G48: 46254.96 | H48: העברה מאת: איטח ענת ו/או רפ 14-362-000321489 איטח ענת ורפי
...

Sheet Feb26
A1: בנק לאומי |
A2: מס' חשבון : ‏‏ ‎885-37554/82‎
A3: תאריך שמירה/הדפסה: 9/2/2026
A5: היתרה | C5: מסגרת האשראי | E5: נכון לתאריך
A7: ₪ 22,270.89 | C7: ₪ 0.00 | E7: 09.02.26
A8: * כולל תנועות היום
A11: 46024 | B11: 46024 | C11: בנק הפועלים | D11: 99012 | E11: 0 | F11: 320 | G11: 38262.12 | H11: העברה מאת: ברייב יולי 12-701-000404014 ועד בית
A12: 46024 | B12: 46024 | C12: בנק מזרחי | D12: 99020 | E12: 0 | F12: 350 | G12: 38612.12 | H12: העברה מאת: רובקין מרגריטה ו 20-444-000494106 וועד בית
A13: 46024 | B13: 46024 | C13: הוראת קבע | D13: 4873628 | E13: 0 | F13: 350 | G13: 38962.12 | H13: העברה מאת: אליזבט בינשטוק, 10-891-003641132 תשלום בהוראת קבע
A14: 46024 | B14: 46024 | C14: מסלול מורחב | D14: 13187 | E14: 25 | F14: 0 | G14: 38937.12
A15: 46024 | B15: 46024 | C15: עמל.ערוץ יש 9 | D15: 9 | E15: 14.85 | F15: 0 | G15: 38922.27 | H15: סכום החיוב מייצג את מספר התנועות שבוצעו בערוץ ישיר/פקיד. מספר התנועות מופיע בסמוך למלל. סכום העמלה לפעולה הינו כפי המופיע בתעריף העמלות ליחיד/תאגיד ובהתאם להטבות הקיימות ללקוח דהיינו סכום חיוב = מספר תנועות ערוץ פקיד/ישיר כפול תעריף העמלה בחשבון הלקוח
A16: 46024 | B16: 46024 | C16: העברה דיגיטל | D16: 255512 | E16: 7000 | F16: 0 | G16: 31922.27 | H16: העברה אל: רוזקום בעמ 12-552-000395129 אינטרקום תשלום 1
A17: 46055 | B17: 46055 | C17: בנק הפועלים | D17: 99012 | E17: 0 | F17: 350 | G17: 32272.27 | H17: העברה מאת: רועי ולי-ש 12-700-000616685 ועד בית
A18: 46055 | B18: 46055 | C18: בנק הפועלים | D18: 99012 | E18: 0 | F18: 350 | G18: 32622.27 | H18: העברה מאת: מנגיסטו דג 12-703-000091338 לוועד הבית
A19: 46055 | B19: 46055 | C19: בנק הפועלים | D19: 99012 | E19: 0 | F19: 867 | G19: 33489.27 | H19: העברה מאת: לגסה סיטוטאו יטא 12-700-000089393 חודש ינואר פברואר
A20: 46055 | B20: 46055 | C20: הוראת קבע | D20: 4668970 | E20: 0 | F20: 350 | G20: 33839.27 | H20: העברה מאת: פריידמן נטליה 10-882-044876260 תשלום
A21: 46055 | B21: 46055 | C21: העברה דיגיטל | D21: 120755 | E21: 0 | F21: 700 | G21: 34539.27 | H21: העברה מאת: פיליפ אלברט 10-916-004497512 חודש פברואר מרץ
A22: 46055 | B22: 46055 | C22: העברה דיגיטל | D22: 121079 | E22: 0 | F22: 60 | G22: 34599.27 | H22: העברה מאת: פיליפ אלברט 10-916-004497512
A23: 46083 | B23: 46083 | C23: הוראת קבע | D23: 4878373 | E23: 0 | F23: 350 | G23: 34949.27 | H23: העברה מאת: גל ברזני, שני ול 10-635-001111123 וועד בית דירה 56
A24: 46083 | B24: 46083 | C24: העברה דיגיטל | D24: 68248 | E24: 7000 | F24: 0 | G24: 27949.27 | H24: העברה אל: רוזקום בעמ 12-552-000395129 אינטרקום תשלום 2
A25: 46144 | B25: 46144 | C25: בנק דיסקונט | D25: 99011 | E25: 0 | F25: 320 | G25: 28269.27 | H25: העברה מאת: אסרף אורטל 11-107-081754738
A26: 46144 | B26: 46144 | C26: בנק אוצר החיל | D26: 99014 | E26: 0 | F26: 350 | G26: 28619.27 | H26: העברה מאת: כחלון שלו ו/או ח 14-350-105236062 וועד בית דירה 25 (הערת לקוח)
... A28: 46144 | B28: 46144 | C28: העברה דיגיטל | D28: 8993 | E28: 900 | F28: 0 | G28: 28069.27 | H28: העברה אל: חלבי כרמי ות 10-981-002104267 גינון
A29: 46175 | B29: 46175 | C29: נובולה בע"מ-י | D29: 42663 | E29: 48.38 | F29: 0 | G29: 28020.89
A30: 46175 | B30: 46175 | C30: הוראת קבע | D30: 4870113 | E30: 0 | F30: 350 | G30: 28370.89 | H30: העברה מאת: היבה ריזק 10-840-002040614 ועד בית דירה 32 קומה 7
A31: 46236 | B31: 46236 | C31: בנק הפועלים | D31: 99012 | E31: 0 | F31: 350 | G31: 28720.89 | H31: העברה מאת: זאדה הודיה וזאדה 12-703-000404555 חודש ינואר משפחת זאדה
A32: 46236 | B32: 46236 | C32: בנק הפועלים | D32: 99012 | E32: 0 | F32: 350 | G32: 29070.89 | H32: העברה מאת: זאדה הודיה 12-703-000404555 תשלום חודשי משפחת זאדה
A33: 46267 | B33: 46267 | C33: הוראת קבע | D33: 4763312 | E33: 0 | F33: 350 | G33: 29420.89 | H33: העברה מאת: יוספה אמור, בנימ 10-885-000271821 תשלום בהוראת קבע
A34: 46267 | B34: 46267 | C34: הוראת קבע | D34: 4899758 | E34: 0 | F34: 350 | G34: 29770.89 | H34: העברה מאת: וולושין אלכסנדר 10-879-057984481 ועד בית
A35: 46267 | B35: 46267 | C35: הוראת קבע | D35: 4932477 | E35: 7500 | F35: 0 | G35: 22270.89 | H35: העברה ל: גל אנתבי 20-505-00159972 תאריך סיום: 09.12.2027 ניקיון האגמית 7
A36: 46297 | B36: 46297 | C36: ש.שלמה חברה-י | D36: 44855 | E36: 982 | F36: 0 | G36: 21288.89
A37: 46297 | B37: 46297 | C37: בנק דיסקונט | D37: 99011 | E37: 0 | F37: 350 | G37: 21638.89 | H37: העברה מאת: שרביט גל,טויזר נ 11-107-205119303 דירה 60
A38: 46297 | B38: 46297 | C38: בנק דיסקונט | D38: 99011 | E38: 0 | F38: 350 | G38: 21988.89 | H38: העברה מאת: סימקין טרוסטיאני 11-097-132698643 ועד הבית - סימקין דירה 21
A39: 46297 | B39: 46297 | C39: בנק דיסקונט | D39: 99011 | E39: 0 | F39: 350 | G39: 22338.89 | H39: העברה מאת: רומנו לינצקי סיו 11-107-075555974
A40: 46297 | B40: 46297 | C40: בנק דיסקונט | D40: 99011 | E40: 0 | F40: 2160 | G40: 24498.89 | H40: העברה מאת: קשר ספורט בע"מ 11-010-001194323 קשר ספורט בע"מ
A41: 46297 | B41: 46297 | C41: בנק הפועלים | D41: 99012 | E41: 0 | F41: 320 | G41: 24818.89 | H41: העברה מאת: אסולין יעק 12-704-000263394 ועד בית
A42: 46297 | B42: 46297 | C42: בנק הפועלים | D42: 99012 | E42: 0 | F42: 350 | G42: 25168.89 | H42: העברה מאת: בייבקוב קו 12-701-000262613 דירה 9
A43: 46297 | B43: 46297 | C43: בנק הפועלים | D43: 99012 | E43: 0 | F43: 350 | G43: 25518.89 | H43: העברה מאת: צ`רניאק בו 12-703-000466089 דירה 44, תשלום ועד
A44: 46297 | B44: 46297 | C44: בנק הפועלים | D44: 99012 | E44: 0 | F44: 350 | G44: 25868.89 | H44: העברה מאת: אל איי הנד 12-703-000496840 ועד דירה 57
A45: 46297 | B45: 46297 | C45: בנק הפועלים | D45: 99012 | E45: 0 | F45: 350 | G45: 26218.89 | H45: העברה מאת: פולונסקי א 12-728-000012111 דירה 52
...

Sheet March26
A1: בנק לאומי |
A2: מס' חשבון : ‏‏ ‎885-37554/82‎
A3: תאריך שמירה/הדפסה: 11/3/2026
A5: היתרה | C5: מסגרת האשראי | E5: נכון לתאריך
A7: ₪ 23,564.48 | C7: ₪ 0.00 | E7: 11.03.26
A8: * כולל תנועות היום
A11: * פירוט הפעולות להיום אינו סופי ועשוי להשתנות / לא להתבצע. יתכן שתהיינה פעולות נוספות שלא מופיעות בשלב זה
A12: תנועות בחשבון
A13: תאריך | B13: תאריך ערך | C13: תיאור | D13: אסמכתא | E13: בחובה | F13: בזכות | G13: היתרה בש"ח | H13: תאור מורחב | I13: הערה
A14: 46025 | B14: 46025 | C14: בזק-הוראות ק-י | D14: 703 | E14: 24.57 | F14: 0 | G14: 28784.59
A15: 46025 | B15: 46025 | C15: נובולה בע"מ-י | D15: 42663 | E15: 77 | F15: 0 | G15: 28707.59
A16: 46025 | B16: 46025 | C16: בנק הפועלים | D16: 99012 | E16: 0 | F16: 320 | G16: 29027.59 | H16: העברה מאת: ברייב יולי 12-701-000404014 ועד בית
A17: 46025 | B17: 46025 | C17: הוראת קבע | D17: 4873628 | E17: 0 | F17: 350 | G17: 29377.59 | H17: העברה מאת: אליזבט בינשטוק, 10-891-003641132 תשלום בהוראת קבע
A18: 46025 | B18: 46025 | C18: מסלול מורחב | D18: 13637 | E18: 25 | F18: 0 | G18: 29352.59
A19: 46025 | B19: 46025 | C19: עמל.ערוץ יש 15 | D19: 15 | E19: 24.75 | F19: 0 | G19: 29327.84 | H19: סכום החיוב מייצג את מספר התנועות שבוצעו בערוץ ישיר/פקיד. מספר התנועות מופיע בסמוך למלל. סכום העמלה לפעולה הינו כפי המופיע בתעריף העמלות ליחיד/תאגיד ובהתאם להטבות הקיימות ללקוח דהיינו סכום חיוב = מספר תנועות ערוץ פקיד/ישיר כפול תעריף העמלה בחשבון הלקוח
A20: 46056 | B20: 46056 | C20: נובולה בע"מ-י | D20: 42663 | E20: 74.25 | F20: 0 | G20: 29253.59
A21: 46056 | B21: 46056 | C21: בנק הפועלים | D21: 99012 | E21: 0 | F21: 350 | G21: 29603.59 | H21: העברה מאת: רועי ולי-ש 12-700-000616685 ועד בית
A22: 46056 | B22: 46056 | C22: בנק הפועלים | D22: 99012 | E22: 0 | F22: 350 | G22: 29953.59 | H22: העברה מאת: מנגיסטו דג 12-703-000091338 לוועד הבית
A23: 46056 | B23: 46056 | C23: הוראת קבע | D23: 4668970 | E23: 0 | F23: 350 | G23: 30303.59 | H23: העברה מאת: פריידמן נטליה 10-882-044876260 תשלום
A24: 46115 | B24: 46115 | C24: הוראת קבע | D24: 4878373 | E24: 0 | F24: 350 | G24: 30653.59 | H24: העברה מאת: גל ברזני, שני ול 10-635-001111123 וועד בית דירה 56
A25: 46145 | B25: 46145 | C25: בנק דיסקונט | D25: 99011 | E25: 0 | F25: 320 | G25: 30973.59 | H25: העברה מאת: אסרף אורטל 11-107-081754738
A26: 46145 | B26: 46145 | C26: בנק אוצר החיל | D26: 99014 | E26: 0 | F26: 350 | G26: 31323.59 | H26: העברה מאת: כחלון שלו ו/או ח 14-350-105236062 וועד בית דירה 25 (הערת לקוח)
A27: 46145 | B27: 46145 | C27: הוראת קבע | D27: 4789577 | E27: 0 | F27: 350 | G27: 31673.59 | H27: העברה מאת: קטרינה שליאק 10-838-002943311 דירה 43 משפחת שליאק
A28: 46145 | B28: 46145 | C28: העברה דיגיטל | D28: 136684 | E28: 900 | F28: 0 | G28: 30773.59 | H28: העברה אל: חלבי כרמי ות 10-981-002104267 גינון
A29: 46176 | B29: 46176 | C29: בנק אוצר החיל | D29: 99014 | E29: 0 | F29: 500 | G29: 31273.59 | H29: העברה מאת: מקייס סאספורתס ק 14-362-105318123 ועד (הערת לקוח)
A30: 46176 | B30: 46176 | C30: הוראת קבע | D30: 4870113 | E30: 0 | F30: 350 | G30: 31623.59 | H30: העברה מאת: היבה ריזק 10-840-002040614 ועד בית דירה 32 קומה 7
A31: 46237 | B31: 46237 | C31: בנק הפועלים | D31: 99012 | E31: 0 | F31: 350 | G31: 31973.59 | H31: העברה מאת: זאדה הודיה 12-703-000404555 תשלום חודשי משפחת זאדה
A32: 46268 | B32: 46268 | C32: הוראת קבע | D32: 4763312 | E32: 0 | F32: 350 | G32: 32323.59 | H32: העברה מאת: יוספה אמור, בנימ 10-885-000271821 תשלום בהוראת קבע
... A34: 46268 | B34: 46268 | C34: הוראת קבע | D34: 4932477 | E34: 7500 | F34: 0 | G34: 25173.59 | H34: העברה ל: גל אנתבי 20-505-00159972 תאריך סיום: 09.12.2027 ניקיון האגמית 7
A35: 46298 | B35: 46298 | C35: ש.שלמה חברה-י | D35: 44855 | E35: 979 | F35: 0 | G35: 24194.59
A36: 46298 | B36: 46298 | C36: בנק דיסקונט | D36: 99011 | E36: 0 | F36: 350 | G36: 24544.59 | H36: העברה מאת: סימקין טרוסטיאני 11-097-132698643 ועד הבית - סימקין דירה 21
A37: 46298 | B37: 46298 | C37: בנק דיסקונט | D37: 99011 | E37: 0 | F37: 350 | G37: 24894.59 | H37: העברה מאת: רומנו לינצקי סיו 11-107-075555974
A38: 46298 | B38: 46298 | C38: בנק דיסקונט | D38: 99011 | E38: 0 | F38: 350 | G38: 25244.59 | H38: העברה מאת: שרביט גל,טויזר נ 11-107-205119303 דירה 60
A39: 46298 | B39: 46298 | C39: בנק הפועלים | D39: 99012 | E39: 0 | F39: 350 | G39: 25594.59 | H39: העברה מאת: בייבקוב קו 12-701-000262613 דירה 9
A40: 46298 | B40: 46298 | C40: בנק הפועלים | D40: 99012 | E40: 0 | F40: 350 | G40: 25944.59 | H40: העברה מאת: צ`רניאק בו 12-703-000466089 דירה 44, תשלום ועד
A41: 46298 | B41: 46298 | C41: בנק הפועלים | D41: 99012 | E41: 0 | F41: 350 | G41: 26294.59 | H41: העברה מאת: אל איי הנד 12-703-000496840 ועד דירה 57
A42: 46298 | B42: 46298 | C42: בנק הפועלים | D42: 99012 | E42: 0 | F42: 350 | G42: 26644.59 | H42: העברה מאת: אסולין יעק 12-704-000263394 ועד בית
A43: 46298 | B43: 46298 | C43: בנק הפועלים | D43: 99012 | E43: 0 | F43: 350 | G43: 26994.59 | H43: העברה מאת: פולונסקי א 12-728-000012111 דירה 52
A44: 46298 | B44: 46298 | C44: בנק הפועלים | D44: 99012 | E44: 0 | F44: 350 | G44: 27344.59 | H44: העברה מאת: מוגילבסקי 12-728-000685973 תשלום וועד דירה 55
A45: 46298 | B45: 46298 | C45: בנק אוצר החיל | D45: 99014 | E45: 0 | F45: 350 | G45: 27694.59 | H45: העברה מאת: כהן אביאל 14-350-000175551 ועד בית
...

Sheet April26
A1: בנק לאומי |
A2: מס' חשבון : ‏‏ ‎885-37554/82‎
A3: תאריך שמירה/הדפסה: 22/4/2026
A5: היתרה | C5: מסגרת האשראי | E5: נכון לתאריך
A7: ₪ 31,251.59 | C7: ₪ 0.00 | E7: 22.04.26
A8: * כולל תנועות היום
A11: * פירוט הפעולות להיום אינו סופי ועשוי להשתנות / לא להתבצע. יתכן שתהיינה פעולות נוספות שלא מופיעות בשלב זה
A12: תנועות בחשבון
A13: תאריך | B13: תאריך ערך | C13: תיאור | D13: אסמכתא | E13: בחובה | F13: בזכות | G13: היתרה בש"ח | H13: תאור מורחב
A14: 46026 | B14: 46026 | C14: הפקדת שיק | D14: 210835 | E14: 0 | F14: 350 | G14: 25205.89
A15: 46026 | B15: 46026 | C15: בנק הפועלים | D15: 99012 | E15: 0 | F15: 320 | G15: 25525.89 | H15: העברה מאת: ברייב יולי 12-701-000404014 ועד בית
A16: 46026 | B16: 46026 | C16: בנק הפועלים | D16: 99012 | E16: 0 | F16: 350 | G16: 25875.89 | H16: העברה מאת: רועי ולי-ש 12-700-000616685 ועד בית
A17: 46026 | B17: 46026 | C17: בנק הפועלים | D17: 99012 | E17: 0 | F17: 350 | G17: 26225.89 | H17: העברה מאת: מנגיסטו דג 12-703-000091338 לוועד הבית
A18: 46026 | B18: 46026 | C18: הוראת קבע | D18: 4873628 | E18: 0 | F18: 350 | G18: 26575.89 | H18: העברה מאת: אליזבט בינשטוק, 10-891-003641132 תשלום בהוראת קבע
A19: 46026 | B19: 46026 | C19: מסלול מורחב | D19: 44842 | E19: 25 | F19: 0 | G19: 26550.89
A20: 46026 | B20: 46026 | C20: עמל.ערוץ יש 16 | D20: 16 | E20: 26.4 | F20: 0 | G20: 26524.49 | H20: סכום החיוב מייצג את מספר התנועות שבוצעו בערוץ ישיר/פקיד. מספר התנועות מופיע בסמוך למלל. סכום העמלה לפעולה הינו כפי המופיע בתעריף העמלות ליחיד/תאגיד ובהתאם להטבות הקיימות ללקוח דהיינו סכום חיוב = מספר תנועות ערוץ פקיד/ישיר כפול תעריף העמלה בחשבון הלקוח
